Workbook
Name Slicer_Representative: #N/A

Sheet Sheet2
A1: Data returned for Count of Call number2, Aug, R03 (First 1000 rows).
A3: calls[Call number] | B3: calls[Customer ID] | C3: calls[Duration] | D3: calls[Representative] | E3: calls[Date of Call] | F3: calls[Purchase Amount] | G3: calls[Satisfaction Rating] | H3: calls[FY] | I3: calls[Day of week] | J3: calls[Duration Bucket] | K3: calls[Rating rounded] | L3: calls[Date of Call (Month)] | M3: calls[Date of Call (Month Index)]
A4: Call_7922 | B4: C0001 | C4: 103 | D4: R03 | E4: 45141 | F4: 117 | G4: 4.7 | H4: 2024 | I4: Thursday | J4: 1 to 2 hours | K4: 5 | L4: Aug | M4: 8
A5: Call_7924 | B5: C0012 | C5: 111 | D5: R03 | E5: 45141 | F5: 99 | G5: 4.1 | H5: 2024 | I5: Thursday | J5: 1 to 2 hours | K5: 4 | L5: Aug | M5: 8
A6: Call_7931 | B6: C0011 | C6: 115 | D6: R03 | E6: 45145 | F6: 40 | G6: 3.3 | H6: 2024 | I6: Monday | J6: 1 to 2 hours | K6: 3 | L6: Aug | M6: 8
A7: Call_7935 | B7: C0010 | C7: 75 | D7: R03 | E7: 45148 | F7: 220 | G7: 4.7 | H7: 2024 | I7: Thursday | J7: 1 to 2 hours | K7: 5 | L7: Aug | M7: 8
A8: Call_7936 | B8: C0003 | C8: 63 | D8: R03 | E8: 45148 | F8: 27 | G8: 3.6 | H8: 2024 | I8: Thursday | J8: 1 to 2 hours | K8: 4 | L8: Aug | M8: 8
A9: Call_7937 | B9: C0013 | C9: 74 | D9: R03 | E9: 45150 | F9: 26 | G9: 4.3 | H9: 2024 | I9: Saturday | J9: 1 to 2 hours | K9: 4 | L9: Aug | M9: 8
A10: Call_7949 | B10: C0002 | C10: 64 | D10: R03 | E10: 45158 | F10: 111 | G10: 3.9 | H10: 2024 | I10: Sunday | J10: 1 to 2 hours | K10: 4 | L10: Aug | M10: 8
A11: Call_7959 | B11: C0001 | C11: 165 | D11: R03 | E11: 45164 | F11: 82 | G11: 3.4 | H11: 2024 | I11: Saturday | J11: More than 2 hours | K11: 3 | L11: Aug | M11: 8
A12: Call_7962 | B12: C0015 | C12: 80 | D12: R03 | E12: 45165 | F12: 104 | G12: 4.7 | H12: 2024 | I12: Sunday | J12: 1 to 2 hours | K12: 5 | L12: Aug | M12: 8
A13: Call_7965 | B13: C0007 | C13: 117 | D13: R03 | E13: 45165 | F13: 90 | G13: 4.1 | H13: 2024 | I13: Sunday | J13: 1 to 2 hours | K13: 4 | L13: Aug | M13: 8
A14: Call_7967 | B14: C0006 | C14: 109 | D14: R03 | E14: 45167 | F14: 68 | G14: 2.3 | H14: 2024 | I14: Tuesday | J14: 1 to 2 hours | K14: 2 | L14: Aug | M14: 8

Sheet calculations
A3: Call Count | B3: Total Amount | C3: Total Duration | D3: Avg. rating | E3: 5* Calls
A4: 1000 | B4: 96623 | C4: 89850 | D4: 3.8854 | E4: 307
A9: Call Count | B9: Total Amount | C9: Total Duration | D9: Avg. rating | E9: 5* Calls
A10: 200 | B10: 20104 | C10: 18209 | D10: 3.8825 | E10: 51
A20: Row Labels | B20: Count of Call number | C20: Count of Call number2
A21: Jan | B21: 21 | C21: 21
A22: Feb | B22: 18 | C22: 18
A23: Mar | B23: 31 | C23: 31 | G23: Row Labels | H23: Count of Call number
A24: Apr | B24: 20 | C24: 20 | G24: Sunday | H24: 27
A25: May | B25: 8 | C25: 8 | G25: Monday | H25: 22
A26: Jun | B26: 12 | C26: 12 | G26: Tuesday | H26: 27
A27: Jul | B27: 12 | C27: 12 | G27: Wednesday | H27: 27
A28: Aug | B28: 7 | C28: 7 | G28: Thursday | H28: 27
A29: Sep | B29: 20 | C29: 20 | G29: Friday | H29: 32
A30: Oct | B30: 24 | C30: 24 | G30: Saturday | H30: 38
A31: Nov | B31: 12 | C31: 12 | G31: Grand Total | H31: 200
A32: Dec | B32: 15 | C32: 15
A33: Grand Total | B33: 200 | C33: 200
F51: for graph | H51: selected rep | I51: =A67 -> R05
A52: Row Labels | B52: Call Count | C52: Total Amount
A53: R01 | B53: 189 | C53: 18415 | F53: Rep | G53: Calls | H53: Amount | I53: Sel. Calls | J53: Sel. Amount
A54: R02 | B54: 218 | C54: 20581 | F54: {=A53:C57} -> R01 | G54: 189 | H54: 18415 | I54: =IF(F54=$I$51,G54,NA()) -> #N/A | J54: =IF(F54=$I$51,H54,NA()) -> #N/A
A55: R03 | B55: 207 | C55: 20872 | F55: R02 | G55: 218 | H55: 20581 | I55: =IF(F55=$I$51,G55,NA()) -> #N/A | J55: =IF(F55=$I$51,H55,NA()) -> #N/A
A56: R04 | B56: 186 | C56: 16651 | F56: R03 | G56: 207 | H56: 20872 | I56: =IF(F56=$I$51,G56,NA()) -> #N/A | J56: =IF(F56=$I$51,H56,NA()) -> #N/A
A57: R05 | B57: 200 | C57: 20104 | F57: R04 | G57: 186 | H57: 16651 | I57: =IF(F57=$I$51,G57,NA()) -> #N/A | J57: =IF(F57=$I$51,H57,NA()) -> #N/A
A58: Grand Total | B58: 1000 | C58: 96623 | F58: R05 | G58: 200 | H58: 20104 | I58: =IF(F58=$I$51,G58,NA()) -> 200 | J58: =IF(F58=$I$51,H58,NA()) -> 20104
A66: Row Labels
A67: R05
C68: Count of Call number | D68: Column Labels
C69: Row Labels | D69: Female | E69: Male | F69: Grand Total
C70: Cincinnati | D70: 144 | E70: 132 | F70: 276
C71: Cleveland | D71: 326 | E71: 63 | F71: 389
C72: Columbus | D72: 129 | E72: 206 | F72: 335
C73: Grand Total | D73: 599 | E73: 401 | F73: 1000
C80: Row Labels | D80: Call Count
C81: 2 | D81: 10
C82: 3 | D82: 44
C83: 4 | D83: 95
C84: 5 | D84: 51
C85: Grand Total | D85: 200
...

Sheet Call-center portfolio
E17: Calls | I17: Amount
P19: R01 | Q19: R02 | R19: R03 | S19: R04 | T19: R05 | U19: TOTAL
O20: =calculations!C96 -> Cincinnati
O21: =calculations!C97 -> C0003 | P21: =calculations!D97 -> 891 | Q21: =calculations!E97 -> 1332 | R21: =calculations!F97 -> 1282 | S21: =calculations!G97 -> 739 | T21: =calculations!H97 -> 560 | U21: =calculations!I97 -> 4804
O22: =calculations!C98 -> C0004 | P22: =calculations!D98 -> 1991 | Q22: =calculations!E98 -> 1886 | R22: =calculations!F98 -> 1206 | S22: =calculations!G98 -> 884 | T22: =calculations!H98 -> 1722 | U22: =calculations!I98 -> 7689
O23: =calculations!C99 -> C0011 | P23: =calculations!D99 -> 1163 | Q23: =calculations!E99 -> 1180 | R23: =calculations!F99 -> 1616 | S23: =calculations!G99 -> 1043 | T23: =calculations!H99 -> 1747 | U23: =calculations!I99 -> 6749
O24: =calculations!C100 -> C0012 | P24: =calculations!D100 -> 1438 | Q24: =calculations!E100 -> 1616 | R24: =calculations!F100 -> 866 | S24: =calculations!G100 -> 829 | T24: =calculations!H100 -> 2070 | U24: =calculations!I100 -> 6819
O25: =calculations!C101 -> Cleveland
O26: =calculations!C102 -> C0002 | P26: =calculations!D102 -> 1233 | Q26: =calculations!E102 -> 223 | R26: =calculations!F102 -> 1680 | S26: =calculations!G102 -> 990 | T26: =calculations!H102 -> 1508 | U26: =calculations!I102 -> 5634
O27: =calculations!C103 -> C0007 | P27: =calculations!D103 -> 1598 | Q27: =calculations!E103 -> 1907 | R27: =calculations!F103 -> 869 | S27: =calculations!G103 -> 1426 | T27: =calculations!H103 -> 1416 | U27: =calculations!I103 -> 7216
O28: =calculations!C104 -> C0008 | P28: =calculations!D104 -> 900 | Q28: =calculations!E104 -> 1016 | R28: =calculations!F104 -> 960 | S28: =calculations!G104 -> 940 | T28: =calculations!H104 -> 1193 | U28: =calculations!I104 -> 5009
O29: =calculations!C105 -> C0010 | P29: =calculations!D105 -> 900 | Q29: =calculations!E105 -> 1470 | R29: =calculations!F105 -> 1617 | S29: =calculations!G105 -> 1314 | T29: =calculations!H105 -> 941 | U29: =calculations!I105 -> 6242
O30: =calculations!C106 -> C0013 | P30: =calculations!D106 -> 1255 | Q30: =calculations!E106 -> 516 | R30: =calculations!F106 -> 1874 | S30: =calculations!G106 -> 1863 | T30: =calculations!H106 -> 1722 | U30: =calculations!I106 -> 7230
O31: =calculations!C107 -> C0015 | P31: =calculations!D107 -> 1138 | Q31: =calculations!E107 -> 1898 | R31: =calculations!F107 -> 1482 | S31: =calculations!G107 -> 846 | T31: =calculations!H107 -> 1154 | U31: =calculations!I107 -> 6518
O32: =calculations!C108 -> Columbus
O33: =calculations!C109 -> C0001 | P33: =calculations!D109 -> 1655 | Q33: =calculations!E109 -> 805 | R33: =calculations!F109 -> 2263 | S33: =calculations!G109 -> 987 | T33: =calculations!H109 -> 1075 | U33: =calculations!I109 -> 6785
O34: =calculations!C110 -> C0005 | P34: =calculations!D110 -> 1104 | Q34: =calculations!E110 -> 2280 | R34: =calculations!F110 -> 1445 | S34: =calculations!G110 -> 1722 | T34: =calculations!H110 -> 1196 | U34: =calculations!I110 -> 7747
O35: =calculations!C111 -> C0006 | P35: =calculations!D111 -> 372 | Q35: =calculations!E111 -> 1818 | R35: =calculations!F111 -> 1346 | S35: =calculations!G111 -> 1156 | T35: =calculations!H111 -> 1484 | U35: =calculations!I111 -> 6176
O36: =calculations!C112 -> C0009 | P36: =calculations!D112 -> 1415 | Q36: =calculations!E112 -> 1271 | R36: =calculations!F112 -> 1214 | S36: =calculations!G112 -> 1135 | T36: =calculations!H112 -> 1566 | U36: =calculations!I112 -> 6601
O37: =calculations!C113 -> C0014 | P37: =calculations!D113 -> 1362 | Q37: =calculations!E113 -> 1363 | R37: =calculations!F113 -> 1152 | S37: =calculations!G113 -> 777 | T37: =calculations!H113 -> 750 | U37: =calculations!I113 -> 5404

Sheet Data
B1: Call Centre Data
B3: Call number | C3: Customer ID | D3: Duration | E3: Representative | F3: Date of Call | G3: Purchase Amount | H3: Satisfaction Rating | I3: FY | J3: Day of week | K3: Duration Bucket | L3: Rating rounded | Q3: Customer ID | R3: Gender | S3: Age | T3: City
B4: Call_7271 | C4: C0003 | D4: 116 | E4: R05 | F4: 44927 | G4: 128 | H4: 4.9 | I4: =IF(MONTH(calls[[#This Row],[Date of Call]])<=6, YEAR(calls[[#This Row],[Date of Call]]), YEAR(calls[[#This Row],[Date of Call]])+1) -> 2023 | J4: =TEXT(calls[[#This Row],[Date of Call]],"DDDD") -> Sunday | K4: {=_xlfn.IFS(calls[[#This Row],[Duration]]<=10,"Under 10 mins", calls[[#This Row],[Duration]]<=30, "10 to 30 mins", calls[[#This Row],[Duration]]<=60, "30 to 60 mins", calls[[#This Row],[Duration]]<=120, "1 to 2 hours", TRUE, "More than 2 hours")} -> 1 to 2 hours | L4: =ROUND(calls[[#This Row],[Satisfaction Rating]],0) -> 5 | Q4: C0001 | R4: Male | S4: 41 | T4: Columbus
B5: Call_7272 | C5: C0004 | D5: 119 | E5: R05 | F5: 44927 | G5: 135 | H5: 2.9 | I5: =IF(MONTH(calls[[#This Row],[Date of Call]])<=6, YEAR(calls[[#This Row],[Date of Call]]), YEAR(calls[[#This Row],[Date of Call]])+1) -> 2023 | J5: =TEXT(calls[[#This Row],[Date of Call]],"DDDD") -> Sunday | K5: {=_xlfn.IFS(calls[[#This Row],[Duration]]<=10,"Under 10 mins", calls[[#This Row],[Duration]]<=30, "10 to 30 mins", calls[[#This Row],[Duration]]<=60, "30 to 60 mins", calls[[#This Row],[Duration]]<=120, "1 to 2 hours", TRUE, "More than 2 hours")} -> 1 to 2 hours | L5: =ROUND(calls[[#This Row],[Satisfaction Rating]],0) -> 3 | Q5: C0002 | R5: Male | S5: 31 | T5: Cleveland
B6: Call_7273 | C6: C0005 | D6: 68 | E6: R02 | F6: 44927 | G6: 66 | H6: 4.7 | I6: =IF(MONTH(calls[[#This Row],[Date of Call]])<=6, YEAR(calls[[#This Row],[Date of Call]]), YEAR(calls[[#This Row],[Date of Call]])+1) -> 2023 | J6: =TEXT(calls[[#This Row],[Date of Call]],"DDDD") -> Sunday | K6: {=_xlfn.IFS(calls[[#This Row],[Duration]]<=10,"Under 10 mins", calls[[#This Row],[Duration]]<=30, "10 to 30 mins", calls[[#This Row],[Duration]]<=60, "30 to 60 mins", calls[[#This Row],[Duration]]<=120, "1 to 2 hours", TRUE, "More than 2 hours")} -> 1 to 2 hours | L6: =ROUND(calls[[#This Row],[Satisfaction Rating]],0) -> 5 | Q6: C0003 | R6: Male | S6: 26 | T6: Cincinnati
B7: Call_7274 | C7: C0014 | D7: 119 | E7: R02 | F7: 44927 | G7: 22 | H7: 2.9 | I7: =IF(MONTH(calls[[#This Row],[Date of Call]])<=6, YEAR(calls[[#This Row],[Date of Call]]), YEAR(calls[[#This Row],[Date of Call]])+1) -> 2023 | J7: =TEXT(calls[[#This Row],[Date of Call]],"DDDD") -> Sunday | K7: {=_xlfn.IFS(calls[[#This Row],[Duration]]<=10,"Under 10 mins", calls[[#This Row],[Duration]]<=30, "10 to 30 mins", calls[[#This Row],[Duration]]<=60, "30 to 60 mins", calls[[#This Row],[Duration]]<=120, "1 to 2 hours", TRUE, "More than 2 hours")} -> 1 to 2 hours | L7: =ROUND(calls[[#This Row],[Satisfaction Rating]],0) -> 3 | Q7: C0004 | R7: Male | S7: 36 | T7: Cincinnati
B8: Call_7275 | C8: C0011 | D8: 128 | E8: R01 | F8: 44928 | G8: 31 | H8: 2.8 | I8: =IF(MONTH(calls[[#This Row],[Date of Call]])<=6, YEAR(calls[[#This Row],[Date of Call]]), YEAR(calls[[#This Row],[Date of Call]])+1) -> 2023 | J8: =TEXT(calls[[#This Row],[Date of Call]],"DDDD") -> Monday | K8: {=_xlfn.IFS(calls[[#This Row],[Duration]]<=10,"Under 10 mins", calls[[#This Row],[Duration]]<=30, "10 to 30 mins", calls[[#This Row],[Duration]]<=60, "30 to 60 mins", calls[[#This Row],[Duration]]<=120, "1 to 2 hours", TRUE, "More than 2 hours")} -> More than 2 hours | L8: =ROUND(calls[[#This Row],[Satisfaction Rating]],0) -> 3 | Q8: C0005 | R8: Male | S8: 37 | T8: Columbus
B9: Call_7276 | C9: C0011 | D9: 49 | E9: R02 | F9: 44929 | G9: 135 | H9: 4.8 | I9: =IF(MONTH(calls[[#This Row],[Date of Call]])<=6, YEAR(calls[[#This Row],[Date of Call]]), YEAR(calls[[#This Row],[Date of Call]])+1) -> 2023 | J9: =TEXT(calls[[#This Row],[Date of Call]],"DDDD") -> Tuesday | K9: {=_xlfn.IFS(calls[[#This Row],[Duration]]<=10,"Under 10 mins", calls[[#This Row],[Duration]]<=30, "10 to 30 mins", calls[[#This Row],[Duration]]<=60, "30 to 60 mins", calls[[#This Row],[Duration]]<=120, "1 to 2 hours", TRUE, "More than 2 hours")} -> 30 to 60 mins | L9: =ROUND(calls[[#This Row],[Satisfaction Rating]],0) -> 5 | Q9: C0006 | R9: Male | S9: 23 | T9: Columbus
B10: Call_7277 | C10: C0007 | D10: 84 | E10: R05 | F10: 44929 | G10: 60 | H10: 4.7 | I10: =IF(MONTH(calls[[#This Row],[Date of Call]])<=6, YEAR(calls[[#This Row],[Date of Call]]), YEAR(calls[[#This Row],[Date of Call]])+1) -> 2023 | J10: =TEXT(calls[[#This Row],[Date of Call]],"DDDD") -> Tuesday | K10: {=_xlfn.IFS(calls[[#This Row],[Duration]]<=10,"Under 10 mins", calls[[#This Row],[Duration]]<=30, "10 to 30 mins", calls[[#This Row],[Duration]]<=60, "30 to 60 mins", calls[[#This Row],[Duration]]<=120, "1 to 2 hours", TRUE, "More than 2 hours")} -> 1 to 2 hours | L10: =ROUND(calls[[#This Row],[Satisfaction Rating]],0) -> 5 | Q10: C0007 | R10: Female | S10: 22 | T10: Cleveland
B11: Call_7278 | C11: C0003 | D11: 103 | E11: R04 | F11: 44929 | G11: 148 | H11: 4.4 | I11: =IF(MONTH(calls[[#This Row],[Date of Call]])<=6, YEAR(calls[[#This Row],[Date of Call]]), YEAR(calls[[#This Row],[Date of Call]])+1) -> 2023 | J11: =TEXT(calls[[#This Row],[Date of Call]],"DDDD") -> Tuesday | K11: {=_xlfn.IFS(calls[[#This Row],[Duration]]<=10,"Under 10 mins", calls[[#This Row],[Duration]]<=30, "10 to 30 mins", calls[[#This Row],[Duration]]<=60, "30 to 60 mins", calls[[#This Row],[Duration]]<=120, "1 to 2 hours", TRUE, "More than 2 hours")} -> 1 to 2 hours | L11: =ROUND(calls[[#This Row],[Satisfaction Rating]],0) -> 4 | Q11: C0008 | R11: Female | S11: 42 | T11: Cleveland
B12: Call_7279 | C12: C0005 | D12: 31 | E12: R02 | F12: 44929 | G12: 135 | H12: 3.6 | I12: =IF(MONTH(calls[[#This Row],[Date of Call]])<=6, YEAR(calls[[#This Row],[Date of Call]]), YEAR(calls[[#This Row],[Date of Call]])+1) -> 2023 | J12: =TEXT(calls[[#This Row],[Date of Call]],"DDDD") -> Tuesday | K12: {=_xlfn.IFS(calls[[#This Row],[Duration]]<=10,"Under 10 mins", calls[[#This Row],[Duration]]<=30, "10 to 30 mins", calls[[#This Row],[Duration]]<=60, "30 to 60 mins", calls[[#This Row],[Duration]]<=120, "1 to 2 hours", TRUE, "More than 2 hours")} -> 30 to 60 mins | L12: =ROUND(calls[[#This Row],[Satisfaction Rating]],0) -> 4 | Q12: C0009 | R12: Female | S12: 25 | T12: Columbus
B13: Call_7280 | C13: C0010 | D13: 44 | E13: R03 | F13: 44929 | G13: 105 | H13: 2.9 | I13: =IF(MONTH(calls[[#This Row],[Date of Call]])<=6, YEAR(calls[[#This Row],[Date of Call]]), YEAR(calls[[#This Row],[Date of Call]])+1) -> 2023 | J13: =TEXT(calls[[#This Row],[Date of Call]],"DDDD") -> Tuesday | K13: {=_xlfn.IFS(calls[[#This Row],[Duration]]<=10,"Under 10 mins", calls[[#This Row],[Duration]]<=30, "10 to 30 mins", calls[[#This Row],[Duration]]<=60, "30 to 60 mins", calls[[#This Row],[Duration]]<=120, "1 to 2 hours", TRUE, "More than 2 hours")} -> 30 to 60 mins | L13: =ROUND(calls[[#This Row],[Satisfaction Rating]],0) -> 3 | Q13: C0010 | R13: Female | S13: 30 | T13: Cleveland
B14: Call_7281 | C14: C0011 | D14: 102 | E14: R02 | F14: 44929 | G14: 69 | H14: 4.9 | I14: =IF(MONTH(calls[[#This Row],[Date of Call]])<=6, YEAR(calls[[#This Row],[Date of Call]]), YEAR(calls[[#This Row],[Date of Call]])+1) -> 2023 | J14: =TEXT(calls[[#This Row],[Date of Call]],"DDDD") -> Tuesday | K14: {=_xlfn.IFS(calls[[#This Row],[Duration]]<=10,"Under 10 mins", calls[[#This Row],[Duration]]<=30, "10 to 30 mins", calls[[#This Row],[Duration]]<=60, "30 to 60 mins", calls[[#This Row],[Duration]]<=120, "1 to 2 hours", TRUE, "More than 2 hours")} -> 1 to 2 hours | L14: =ROUND(calls[[#This Row],[Satisfaction Rating]],0) -> 5 | Q14: C0011 | R14: Female | S14: 30 | T14: Cincinnati
B15: Call_7282 | C15: C0013 | D15: 135 | E15: R05 | F15: 44929 | G15: 46 | H15: 3.4 | I15: =IF(MONTH(calls[[#This Row],[Date of Call]])<=6, YEAR(calls[[#This Row],[Date of Call]]), YEAR(calls[[#This Row],[Date of Call]])+1) -> 2023 | J15: =TEXT(calls[[#This Row],[Date of Call]],"DDDD") -> Tuesday | K15: {=_xlfn.IFS(calls[[#This Row],[Duration]]<=10,"Under 10 mins", calls[[#This Row],[Duration]]<=30, "10 to 30 mins", calls[[#This Row],[Duration]]<=60, "30 to 60 mins", calls[[#This Row],[Duration]]<=120, "1 to 2 hours", TRUE, "More than 2 hours")} -> More than 2 hours | L15: =ROUND(calls[[#This Row],[Satisfaction Rating]],0) -> 3 | Q15: C0012 | R15: Female | S15: 28 | T15: Cincinnati
... B18: Call_7285 | C18: C0013 | D18: 48 | E18: R01 | F18: 44930 | G18: 68 | H18: 4.9 | I18: =IF(MONTH(calls[[#This Row],[Date of Call]])<=6, YEAR(calls[[#This Row],[Date of Call]]), YEAR(calls[[#This Row],[Date of Call]])+1) -> 2023 | J18: =TEXT(calls[[#This Row],[Date of Call]],"DDDD") -> Wednesday | K18: {=_xlfn.IFS(calls[[#This Row],[Duration]]<=10,"Under 10 mins", calls[[#This Row],[Duration]]<=30, "10 to 30 mins", calls[[#This Row],[Duration]]<=60, "30 to 60 mins", calls[[#This Row],[Duration]]<=120, "1 to 2 hours", TRUE, "More than 2 hours")} -> 30 to 60 mins | L18: =ROUND(calls[[#This Row],[Satisfaction Rating]],0) -> 5 | Q18: C0015 | R18: Female | S18: 43 | T18: Cleveland
B19: Call_7286 | C19: C0010 | D19: 176 | E19: R05 | F19: 44931 | G19: 24 | H19: 4.8 | I19: =IF(MONTH(calls[[#This Row],[Date of Call]])<=6, YEAR(calls[[#This Row],[Date of Call]]), YEAR(calls[[#This Row],[Date of Call]])+1) -> 2023 | J19: =TEXT(calls[[#This Row],[Date of Call]],"DDDD") -> Thursday | K19: {=_xlfn.IFS(calls[[#This Row],[Duration]]<=10,"Under 10 mins", calls[[#This Row],[Duration]]<=30, "10 to 30 mins", calls[[#This Row],[Duration]]<=60, "30 to 60 mins", calls[[#This Row],[Duration]]<=120, "1 to 2 hours", TRUE, "More than 2 hours")} -> More than 2 hours | L19: =ROUND(calls[[#This Row],[Satisfaction Rating]],0) -> 5
B20: Call_7287 | C20: C0010 | D20: 99 | E20: R01 | F20: 44931 | G20: 195 | H20: 3.9 | I20: =IF(MONTH(calls[[#This Row],[Date of Call]])<=6, YEAR(calls[[#This Row],[Date of Call]]), YEAR(calls[[#This Row],[Date of Call]])+1) -> 2023 | J20: =TEXT(calls[[#This Row],[Date of Call]],"DDDD") -> Thursday | K20: {=_xlfn.IFS(calls[[#This Row],[Duration]]<=10,"Under 10 mins", calls[[#This Row],[Duration]]<=30, "10 to 30 mins", calls[[#This Row],[Duration]]<=60, "30 to 60 mins", calls[[#This Row],[Duration]]<=120, "1 to 2 hours", TRUE, "More than 2 hours")} -> 1 to 2 hours | L20: =ROUND(calls[[#This Row],[Satisfaction Rating]],0) -> 4
B21: Call_7288 | C21: C0009 | D21: 28 | E21: R03 | F21: 44931 | G21: 28 | H21: 3.8 | I21: =IF(MONTH(calls[[#This Row],[Date of Call]])<=6, YEAR(calls[[#This Row],[Date of Call]]), YEAR(calls[[#This Row],[Date of Call]])+1) -> 2023 | J21: =TEXT(calls[[#This Row],[Date of Call]],"DDDD") -> Thursday | K21: {=_xlfn.IFS(calls[[#This Row],[Duration]]<=10,"Under 10 mins", calls[[#This Row],[Duration]]<=30, "10 to 30 mins", calls[[#This Row],[Duration]]<=60, "30 to 60 mins", calls[[#This Row],[Duration]]<=120, "1 to 2 hours", TRUE, "More than 2 hours")} -> 10 to 30 mins | L21: =ROUND(calls[[#This Row],[Satisfaction Rating]],0) -> 4
B22: Call_7289 | C22: C0007 | D22: 54 | E22: R02 | F22: 44931 | G22: 170 | H22: 4.3 | I22: =IF(MONTH(calls[[#This Row],[Date of Call]])<=6, YEAR(calls[[#This Row],[Date of Call]]), YEAR(calls[[#This Row],[Date of Call]])+1) -> 2023 | J22: =TEXT(calls[[#This Row],[Date of Call]],"DDDD") -> Thursday | K22: {=_xlfn.IFS(calls[[#This Row],[Duration]]<=10,"Under 10 mins", calls[[#This Row],[Duration]]<=30, "10 to 30 mins", calls[[#This Row],[Duration]]<=60, "30 to 60 mins", calls[[#This Row],[Duration]]<=120, "1 to 2 hours", TRUE, "More than 2 hours")} -> 30 to 60 mins | L22: =ROUND(calls[[#This Row],[Satisfaction Rating]],0) -> 4
B23: Call_7290 | C23: C0006 | D23: 48 | E23: R05 | F23: 44932 | G23: 30 | H23: 4.4 | I23: =IF(MONTH(calls[[#This Row],[Date of Call]])<=6, YEAR(calls[[#This Row],[Date of Call]]), YEAR(calls[[#This Row],[Date of Call]])+1) -> 2023 | J23: =TEXT(calls[[#This Row],[Date of Call]],"DDDD") -> Friday | K23: {=_xlfn.IFS(calls[[#This Row],[Duration]]<=10,"Under 10 mins", calls[[#This Row],[Duration]]<=30, "10 to 30 mins", calls[[#This Row],[Duration]]<=60, "30 to 60 mins", calls[[#This Row],[Duration]]<=120, "1 to 2 hours", TRUE, "More than 2 hours")} -> 30 to 60 mins | L23: =ROUND(calls[[#This Row],[Satisfaction Rating]],0) -> 4
B24: Call_7291 | C24: C0004 | D24: 128 | E24: R05 | F24: 44932 | G24: 72 | H24: 5 | I24: =IF(MONTH(calls[[#This Row],[Date of Call]])<=6, YEAR(calls[[#This Row],[Date of Call]]), YEAR(calls[[#This Row],[Date of Call]])+1) -> 2023 | J24: =TEXT(calls[[#This Row],[Date of Call]],"DDDD") -> Friday | K24: {=_xlfn.IFS(calls[[#This Row],[Duration]]<=10,"Under 10 mins", calls[[#This Row],[Duration]]<=30, "10 to 30 mins", calls[[#This Row],[Duration]]<=60, "30 to 60 mins", calls[[#This Row],[Duration]]<=120, "1 to 2 hours", TRUE, "More than 2 hours")} -> More than 2 hours | L24: =ROUND(calls[[#This Row],[Satisfaction Rating]],0) -> 5
B25: Call_7292 | C25: C0004 | D25: 38 | E25: R04 | F25: 44933 | G25: 92 | H25: 4.9 | I25: =IF(MONTH(calls[[#This Row],[Date of Call]])<=6, YEAR(calls[[#This Row],[Date of Call]]), YEAR(calls[[#This Row],[Date of Call]])+1) -> 2023 | J25: =TEXT(calls[[#This Row],[Date of Call]],"DDDD") -> Saturday | K25: {=_xlfn.IFS(calls[[#This Row],[Duration]]<=10,"Under 10 mins", calls[[#This Row],[Duration]]<=30, "10 to 30 mins", calls[[#This Row],[Duration]]<=60, "30 to 60 mins", calls[[#This Row],[Duration]]<=120, "1 to 2 hours", TRUE, "More than 2 hours")} -> 30 to 60 mins | L25: =ROUND(calls[[#This Row],[Satisfaction Rating]],0) -> 5
B26: Call_7293 | C26: C0003 | D26: 67 | E26: R04 | F26: 44934 | G26: 165 | H26: 4.5 | I26: =IF(MONTH(calls[[#This Row],[Date of Call]])<=6, YEAR(calls[[#This Row],[Date of Call]]), YEAR(calls[[#This Row],[Date of Call]])+1) -> 2023 | J26: =TEXT(calls[[#This Row],[Date of Call]],"DDDD") -> Sunday | K26: {=_xlfn.IFS(calls[[#This Row],[Duration]]<=10,"Under 10 mins", calls[[#This Row],[Duration]]<=30, "10 to 30 mins", calls[[#This Row],[Duration]]<=60, "30 to 60 mins", calls[[#This Row],[Duration]]<=120, "1 to 2 hours", TRUE, "More than 2 hours")} -> 1 to 2 hours | L26: =ROUND(calls[[#This Row],[Satisfaction Rating]],0) -> 5
B27: Call_7294 | C27: C0015 | D27: 58 | E27: R02 | F27: 44934 | G27: 140 | H27: 2.1 | I27: =IF(MONTH(calls[[#This Row],[Date of Call]])<=6, YEAR(calls[[#This Row],[Date of Call]]), YEAR(calls[[#This Row],[Date of Call]])+1) -> 2023 | J27: =TEXT(calls[[#This Row],[Date of Call]],"DDDD") -> Sunday | K27: {=_xlfn.IFS(calls[[#This Row],[Duration]]<=10,"Under 10 mins", calls[[#This Row],[Duration]]<=30, "10 to 30 mins", calls[[#This Row],[Duration]]<=60, "30 to 60 mins", calls[[#This Row],[Duration]]<=120, "1 to 2 hours", TRUE, "More than 2 hours")} -> 30 to 60 mins | L27: =ROUND(calls[[#This Row],[Satisfaction Rating]],0) -> 2
B28: Call_7295 | C28: C0010 | D28: 54 | E28: R01 | F28: 44934 | G28: 111 | H28: 3.3 | I28: =IF(MONTH(calls[[#This Row],[Date of Call]])<=6, YEAR(calls[[#This Row],[Date of Call]]), YEAR(calls[[#This Row],[Date of Call]])+1) -> 2023 | J28: =TEXT(calls[[#This Row],[Date of Call]],"DDDD") -> Sunday | K28: {=_xlfn.IFS(calls[[#This Row],[Duration]]<=10,"Under 10 mins", calls[[#This Row],[Duration]]<=30, "10 to 30 mins", calls[[#This Row],[Duration]]<=60, "30 to 60 mins", calls[[#This Row],[Duration]]<=120, "1 to 2 hours", TRUE, "More than 2 hours")} -> 30 to 60 mins | L28: =ROUND(calls[[#This Row],[Satisfaction Rating]],0) -> 3
B29: Call_7296 | C29: C0012 | D29: 28 | E29: R05 | F29: 44935 | G29: 63 | H29: 4.1 | I29: =IF(MONTH(calls[[#This Row],[Date of Call]])<=6, YEAR(calls[[#This Row],[Date of Call]]), YEAR(calls[[#This Row],[Date of Call]])+1) -> 2023 | J29: =TEXT(calls[[#This Row],[Date of Call]],"DDDD") -> Monday | K29: {=_xlfn.IFS(calls[[#This Row],[Duration]]<=10,"Under 10 mins", calls[[#This Row],[Duration]]<=30, "10 to 30 mins", calls[[#This Row],[Duration]]<=60, "30 to 60 mins", calls[[#This Row],[Duration]]<=120, "1 to 2 hours", TRUE, "More than 2 hours")} -> 10 to 30 mins | L29: =ROUND(calls[[#This Row],[Satisfaction Rating]],0) -> 4
B30: Call_7297 | C30: C0002 | D30: 73 | E30: R05 | F30: 44935 | G30: 80 | H30: 4.2 | I30: =IF(MONTH(calls[[#This Row],[Date of Call]])<=6, YEAR(calls[[#This Row],[Date of Call]]), YEAR(calls[[#This Row],[Date of Call]])+1) -> 2023 | J30: =TEXT(calls[[#This Row],[Date of Call]],"DDDD") -> Monday | K30: {=_xlfn.IFS(calls[[#This Row],[Duration]]<=10,"Under 10 mins", calls[[#This Row],[Duration]]<=30, "10 to 30 mins", calls[[#This Row],[Duration]]<=60, "30 to 60 mins", calls[[#This Row],[Duration]]<=120, "1 to 2 hours", TRUE, "More than 2 hours")} -> 1 to 2 hours | L30: =ROUND(calls[[#This Row],[Satisfaction Rating]],0) -> 4
... B1003: Call_8270 | C1003: C0009 | D1003: 114 | E1003: R01 | F1003: 45291 | G1003: 40 | H1003: 3.9 | I1003: =IF(MONTH(calls[[#This Row],[Date of Call]])<=6, YEAR(calls[[#This Row],[Date of Call]]), YEAR(calls[[#This Row],[Date of Call]])+1) -> 2024 | J1003: =TEXT(calls[[#This Row],[Date of Call]],"DDDD") -> Sunday | K1003: {=_xlfn.IFS(calls[[#This Row],[Duration]]<=10,"Under 10 mins", calls[[#This Row],[Duration]]<=30, "10 to 30 mins", calls[[#This Row],[Duration]]<=60, "30 to 60 mins", calls[[#This Row],[Duration]]<=120, "1 to 2 hours", TRUE, "More than 2 hours")} -> 1 to 2 hours | L1003: =ROUND(calls[[#This Row],[Satisfaction Rating]],0) -> 4

Sheet Assets
E2: Rep ID | F2: Rep Image
E3: R01
E4: R02
E5: R03
E6: R04
E7: R05
J8: =Assets!F3 -> 0
